Workbook
Name pe_direito: Quantitativos!$C$4
Name parede_e_comp: Quantitativos!$C$5
Name janela_l: Quantitativos!$C$6
Name janela_h: Quantitativos!$C$7
Name parede_c_comp: Quantitativos!$C$8
Name bwc_trechos: Quantitativos!$C$9
Name porta_bwc_l: Quantitativos!$C$10
Name porta_h: Quantitativos!$C$11
Name faixa: Quantitativos!$C$12
Name porta_ent_l: Quantitativos!$C$13
Name parede_d_comp: Quantitativos!$C$14
Name teto_faixa_l: Quantitativos!$C$15
Name area_e: Quantitativos!$C$16
Name area_c: Quantitativos!$C$17
Name area_bwc: Quantitativos!$C$18
Name area_leste: Quantitativos!$C$19
Name area_paredes: Quantitativos!$C$20
Name area_teto: Quantitativos!$C$21
Name area_pintura_total: Quantitativos!$C$22
Name area_ripado: Quantitativos!$C$23
Name demaos_parede: Quantitativos!$C$24
Name demaos_teto: Quantitativos!$C$25
Name perda_tinta: Quantitativos!$C$26
Name rend_galao: Quantitativos!$C$27
Name galoes_parede: Quantitativos!$C$28
Name galoes_teto: Quantitativos!$C$29
Name led_prateleira: Quantitativos!$C$30
Name led_vertical: Quantitativos!$C$31
Name led_nichos: Quantitativos!$C$32
Name n_verticais: Quantitativos!$C$33
Name perda_led: Quantitativos!$C$34
Name metros_led: Quantitativos!$C$35
Name rolos_led: Quantitativos!$C$36
Name barras_perfil: Quantitativos!$C$37
Name n_verticais_prem: Quantitativos!$C$38
Name metros_led_prem: Quantitativos!$C$39
Name rolos_led_prem: Quantitativos!$C$40
Name barras_perfil_prem: Quantitativos!$C$41
Name contingencia: Quantitativos!$C$42

Sheet Resumo
A1: Resumo do orçamento — Suíte 01 (quarto + escritório)
A2: Valores em R$. Preços consultados em 30/10/2026. Linhas em laranja nas abas = estimativas. Teto de orçamento: não informado.
A4: Categoria | B4: Econômico | C4: Equilibrado | D4: Premium
A5: Mobiliário | B5: =SUMIF('Econômico'!$A:$A,$A5,'Econômico'!$M:$M) | C5: =SUMIF('Equilibrado'!$A:$A,$A5,'Equilibrado'!$M:$M) | D5: =SUMIF('Premium'!$A:$A,$A5,'Premium'!$M:$M)
A6: Marcenaria | B6: =SUMIF('Econômico'!$A:$A,$A6,'Econômico'!$M:$M) | C6: =SUMIF('Equilibrado'!$A:$A,$A6,'Equilibrado'!$M:$M) | D6: =SUMIF('Premium'!$A:$A,$A6,'Premium'!$M:$M)
A7: Iluminação | B7: =SUMIF('Econômico'!$A:$A,$A7,'Econômico'!$M:$M) | C7: =SUMIF('Equilibrado'!$A:$A,$A7,'Equilibrado'!$M:$M) | D7: =SUMIF('Premium'!$A:$A,$A7,'Premium'!$M:$M)
A8: Pintura | B8: =SUMIF('Econômico'!$A:$A,$A8,'Econômico'!$M:$M) | C8: =SUMIF('Equilibrado'!$A:$A,$A8,'Equilibrado'!$M:$M) | D8: =SUMIF('Premium'!$A:$A,$A8,'Premium'!$M:$M)
A9: Complementares | B9: =SUMIF('Econômico'!$A:$A,$A9,'Econômico'!$M:$M) | C9: =SUMIF('Equilibrado'!$A:$A,$A9,'Equilibrado'!$M:$M) | D9: =SUMIF('Premium'!$A:$A,$A9,'Premium'!$M:$M)
A10: Decoração (opcional) | B10: =SUMIF('Econômico'!$A:$A,$A10,'Econômico'!$M:$M) | C10: =SUMIF('Equilibrado'!$A:$A,$A10,'Equilibrado'!$M:$M) | D10: =SUMIF('Premium'!$A:$A,$A10,'Premium'!$M:$M)
A11: Serviços | B11: =SUMIF('Econômico'!$A:$A,$A11,'Econômico'!$M:$M) | C11: =SUMIF('Equilibrado'!$A:$A,$A11,'Equilibrado'!$M:$M) | D11: =SUMIF('Premium'!$A:$A,$A11,'Premium'!$M:$M)
A12: Subtotal itens | B12: =SUM(B5:B11) | C12: =SUM(C5:C11) | D12: =SUM(D5:D11)
A13: Reserva para imprevistos (10%) | B13: =B12*contingencia | C13: =C12*contingencia | D13: =D12*contingencia
A14: TOTAL | B14: =B12+B13 | C14: =C12+C13 | D14: =D12+D13
A16: dos quais: preços pesquisados | B16: =SUMIF('Econômico'!$H:$H,"Pesquisado (página do produto)",'Econômico'!$M:$M)+SUMIF('Econômico'!$H:$H,"Pesquisado (listagem da loja)",'Econômico'!$M:$M) | C16: =SUMIF('Equilibrado'!$H:$H,"Pesquisado (página do produto)",'Equilibrado'!$M:$M)+SUMIF('Equilibrado'!$H:$H,"Pesquisado (listagem da loja)",'Equilibrado'!$M:$M) | D16: =SUMIF('Premium'!$H:$H,"Pesquisado (página do produto)",'Premium'!$M:$M)+SUMIF('Premium'!$H:$H,"Pesquisado (listagem da loja)",'Premium'!$M:$M)
A17: dos quais: estimativas | B17: =SUMIF('Econômico'!$H:$H,"Estimativa",'Econômico'!$M:$M) | C17: =SUMIF('Equilibrado'!$H:$H,"Estimativa",'Equilibrado'!$M:$M) | D17: =SUMIF('Premium'!$H:$H,"Estimativa",'Premium'!$M:$M)
A19: Notas:
A20: • Piso de madeira colante: fora do orçamento, conforme combinado.
A21: • Preços Pichau = à vista no PIX. Amazon = preço do anúncio no dia; frete pode variar por CEP.
A22: • Tinta grafite: o preço é o da base branca; a cor preparada em loja pode custar mais. Confirmar na loja.
A23: • Marcenaria (ripado, tampo, prateleira) e mão de obra = estimativas por faixa de mercado; pedir 3 orçamentos locais.
A24: • Premium: a estrutura Marsail é vendida pela Amazon Global (importação); prazo e impostos podem variar.

Sheet Econômico
A1: Orçamento — cenário Econômico (preços consultados em 30/10/2026)
A3: Categoria | B3: Item | C3: Produto / especificação | D3: Loja / fornecedor | E3: Link / fonte | F3: Dimensões L×P×A (cm) | G3: Material | H3: Status do preço | I3: Data | J3: Qtd | K3: Unid. | L3: Preço unit. | M3: Subtotal
A4: Mobiliário | B4: Mesa regulável elétrica | C4: Pichau Starlift Pro 160×70 (1 motor, 80 kg, tampo MDP 15 mm) | D4: Pichau | E4: https://www.pichau.com.br/mesa-pichau-starlift-pro-com-regulagem-de-altura-160x80cm-preto | F4: 160 × 70 × 73–118 | G4: Aço + MDP melamina preto | H4: Pesquisado (página do produto) | I4: 30/10/2026 | J4: 1 | K4: un | L4: 823.99 | M4: =J4*L4
A5: Mobiliário | B5: Placa de reforço p/ braço (tampo de 15 mm) | C5: Placa de reforço de montagem de monitor (aço) | D5: Amazon | E5: https://www.amazon.com.br/dp/B0FSXG2BJ5 | F5: — | G5: Aço | H5: Pesquisado (listagem da loja) | I5: 30/10/2026 | J5: 1 | K5: un | L5: 161.4 | M5: =J5*L5
A6: Mobiliário | B6: Cadeira ergonômica | C6: DT3 Worka Preto 14961-1 | D6: Pichau | E6: https://www.pichau.com.br/cadeira-ergonomica-dt3-worka-preto-14961-1 | F6: não declarada (est. 65 × 65) | G6: Tela/nylon | H6: Pesquisado (listagem da loja) | I6: 30/10/2026 | J6: 1 | K6: un | L6: 749.99 | M6: =J6*L6
A7: Mobiliário | B7: Cama box + colchão solteiro | C7: Cama Box Solteiro Colchão Molas Qatar | D7: Amazon | E7: https://www.amazon.com.br/dp/B0C4648NG8 | F7: 88 × 188 × 60 | G7: Molas + base box | H7: Pesquisado (listagem da loja) | I7: 30/10/2026 | J7: 1 | K7: un | L7: 630.83 | M7: =J7*L7
A8: Mobiliário | B8: Braço articulado 2 monitores | C8: Braço duplo pistão a gás 13–27" (2–9 kg) — NÃO serve ultrawide 34" | D8: Amazon | E8: https://www.amazon.com.br/dp/B0H6NHQXHW | F8: — | G8: Aço/alumínio | H8: Pesquisado (listagem da loja) | I8: 30/10/2026 | J8: 1 | K8: un | L8: 157.69 | M8: =J8*L8
A9: Marcenaria | B9: Painel ripado Parede D (piso→teto) | C9: Ripado MDF BP amadeirado sobre fundo preto, instalado | D9: Marceneiro local | E9: Faixa R$ 250–600/m² instalado (Revista Oeste); R$ 180–750/m² (Monitor do Mercado) — https://monitordomercado.com.br/economia-2/385193-quanto-custa-instalar-painel-ripado-e-transformar-a-sala-com-um-visual-moderno-e-sofisticado/ | F9: 265 × 3 × 264 | G9: MDF BP | H9: Estimativa | I9: 30/10/2026 | J9: =area_ripado | K9: m² | L9: 250 | M9: =J9*L9
A10: Marcenaria | B10: Prateleiras sobre a mesa | C10: Prateleira MDF Freijó 80×25 c/ suporte invisível (kit 2) | D10: Amazon | E10: https://www.amazon.com.br/dp/B0HPF7JM1G | F10: 2 × (80 × 25) | G10: MDF freijó | H10: Pesquisado (listagem da loja) | I10: 30/10/2026 | J10: 1 | K10: kit | L10: 436 | M10: =J10*L10
A11: Marcenaria | B11: Nichos iluminados 3× (cabeceira) | C11: MDF BP freijó 15 mm, fundo preto, rasgo p/ LED | D11: Marceneiro local | E11: Estimativa | F11: 3 × (24 × 26 × 16) | G11: MDF BP freijó | H11: Estimativa | I11: 30/10/2026 | J11: 1 | K11: vb | L11: 300 | M11: =J11*L11
A12: Iluminação | B12: Fita LED COB 3000 K | C12: Fita LED COB 24V 15W/m 480 LEDs 3000K 5 m | D12: Amazon | E12: https://www.amazon.com.br/dp/B0GBY67PN3 | F12: 5 m | G12: — | H12: Pesquisado (listagem da loja) | I12: 30/10/2026 | J12: =rolos_led | K12: rolo | L12: 74.95 | M12: =J12*L12
A13: Iluminação | B13: Fonte 24 V | C13: Fonte chaveada slim 24V 5A 120W bivolt | D13: Amazon | E13: https://www.amazon.com.br/dp/B0H7CQ2BY2 | F13: — | G13: — | H13: Pesquisado (listagem da loja) | I13: 30/10/2026 | J13: 1 | K13: un | L13: 61.99 | M13: =J13*L13
A14: Iluminação | B14: Perfil de alumínio p/ LED | C14: Perfil LED embutir 24×7 mm slim 2 m preto | D14: Amazon | E14: https://www.amazon.com.br/dp/B0F1ZBZZTP | F14: 200 cm | G14: Alumínio | H14: Pesquisado (listagem da loja) | I14: 30/10/2026 | J14: =barras_perfil | K14: barra | L14: 29.9 | M14: =J14*L14
A15: Iluminação | B15: Dimmer da fita | C15: Controle remoto IR c/ dimmer 12/24V | D15: Amazon | E15: https://www.amazon.com.br/dp/B0FJH6572V | F15: — | G15: — | H15: Pesquisado (listagem da loja) | I15: 30/10/2026 | J15: 1 | K15: un | L15: 31.5 | M15: =J15*L15
A16: Iluminação | B16: Barra de luz p/ monitor | C16: Luminária p/ monitor 3 temperaturas, toque | D16: Amazon | E16: https://www.amazon.com.br/dp/B0GXZ9CN8M | F16: — | G16: — | H16: Pesquisado (listagem da loja) | I16: 30/10/2026 | J16: 1 | K16: un | L16: 56.99 | M16: =J16*L16
A17: Iluminação | B17: Arandela da cama | C17: Arandela tubo articulada preta c/ interruptor (conferir se tem plugue) | D17: Amazon | E17: https://www.amazon.com.br/dp/B0DND64VLW | F17: — | G17: Metal | H17: Pesquisado (listagem da loja) | I17: 30/10/2026 | J17: 1 | K17: un | L17: 74.95 | M17: =J17*L17
A18: Iluminação | B18: Lâmpadas 3000 K (ventilador/teto) | C18: LEDVANCE OSRAM CLA60 9W 3000K E27 (kit 10) | D18: Amazon | E18: https://www.amazon.com.br/dp/B0HNY3SPM6 | F18: — | G18: — | H18: Pesquisado (listagem da loja) | I18: 30/10/2026 | J18: 1 | K18: kit | L18: 69.9 | M18: =J18*L18
A19: Pintura | B19: Tinta paredes (grafite) | C19: Coral Coralar acrílica 3,6 L — preço da base; cor grafite preparada em loja (conferir) | D19: Amazon | E19: https://www.amazon.com.br/dp/B0G62TWLCN | F19: 3,6 L | G19: Acrílica fosca | H19: Pesquisado (listagem da loja) | I19: 30/10/2026 | J19: =galoes_parede | K19: galão | L19: 61.74 | M19: =J19*L19
A20: Pintura | B20: Tinta teto (branco) | C20: Coral Coralar acrílica Branco 3,6 L | D20: Amazon | E20: https://www.amazon.com.br/dp/B0G62TCBGG | F20: 3,6 L | G20: Acrílica | H20: Pesquisado (listagem da loja) | I20: 30/10/2026 | J20: =galoes_teto | K20: galão | L20: 61.74 | M20: =J20*L20
A21: Pintura | B21: Kit pintura | C21: Kit anti-gotas rolos 23/9 cm, bandeja, suporte e trincha | D21: Amazon | E21: https://www.amazon.com.br/dp/B0H6CMVSRL | F21: — | G21: — | H21: Pesquisado (listagem da loja) | I21: 30/10/2026 | J21: 1 | K21: kit | L21: 31.99 | M21: =J21*L21
A22: Pintura | B22: Fita crepe | C22: Kit 2 fitas crepe 48 mm × 50 m | D22: Amazon | E22: https://www.amazon.com.br/dp/B0H8BCLC4J | F22: — | G22: — | H22: Pesquisado (listagem da loja) | I22: 30/10/2026 | J22: 1 | K22: kit | L22: 29.8 | M22: =J22*L22
A23: Pintura | B23: Proteção de piso/móveis | C23: Lona protetora c/ fita 1,5 × 10 m | D23: Amazon | E23: https://www.amazon.com.br/dp/B0GVPX4YVY | F23: — | G23: — | H23: Pesquisado (listagem da loja) | I23: 30/10/2026 | J23: 1 | K23: un | L23: 15.9 | M23: =J23*L23
A24: Pintura | B24: Massa/reparos pontuais | C24: Massa corrida + lixa (reparos) | D24: — | E24: Estimativa | F24: — | G24: — | H24: Estimativa | I24: 30/10/2026 | J24: 1 | K24: vb | L24: 60 | M24: =J24*L24
A25: Complementares | B25: Tapete | C25: Tapete pelo baixo c/ relevo cinza escuro 2,00 × 1,40 | D25: Amazon | E25: https://www.amazon.com.br/dp/B0GXCDQG6W | F25: 140 × 200 | G25: Sintético | H25: Pesquisado (listagem da loja) | I25: 30/10/2026 | J25: 1 | K25: un | L25: 142.4 | M25: =J25*L25
A26: Complementares | B26: Filtro de linha c/ DPS | C26: iCLAMPER Energia 5 tomadas | D26: Amazon | E26: https://www.amazon.com.br/dp/B0D8V17JSG | F26: — | G26: — | H26: Pesquisado (listagem da loja) | I26: 30/10/2026 | J26: 1 | K26: un | L26: 71.98 | M26: =J26*L26
A27: Complementares | B27: Prolongador da tomada (ripado) | C27: Margirius prolongador caixa 4×2 | D27: Amazon | E27: https://www.amazon.com.br/dp/B089M44PPG | F27: — | G27: — | H27: Pesquisado (listagem da loja) | I27: 30/10/2026 | J27: 1 | K27: un | L27: 23.27 | M27: =J27*L27
A28: Complementares | B28: Organização de cabos | C28: Organizador de fios 19 mm × 1,5 m | D28: Amazon | E28: https://www.amazon.com.br/dp/B08R58CWKD | F28: — | G28: — | H28: Pesquisado (listagem da loja) | I28: 30/10/2026 | J28: 1 | K28: un | L28: 16.17 | M28: =J28*L28
A29: Complementares | B29: Abraçadeiras | C29: Abraçadeira nylon preta 2,5 × 100 mm (100 un) | D29: Amazon | E29: https://www.amazon.com.br/dp/B0GWNHFSCY | F29: — | G29: — | H29: Pesquisado (listagem da loja) | I29: 30/10/2026 | J29: 1 | K29: pct | L29: 10.2 | M29: =J29*L29
A30: Complementares | B30: Suporte de notebook | C30: Suporte dobrável alumínio c/ regulagem | D30: Amazon | E30: https://www.amazon.com.br/dp/B0H13G1VTW | F30: — | G30: Alumínio | H30: Pesquisado (listagem da loja) | I30: 30/10/2026 | J30: 1 | K30: un | L30: 65.78 | M30: =J30*L30
A31: Decoração (opcional) | B31: Luminária de mesa articulada | C31: Luminária articulada preta, E27, lâmpada 2700 K | D31: A pesquisar | E31: Estimativa (preço não pesquisado) | F31: — | G31: — | H31: Estimativa | I31: 30/10/2026 | J31: 1 | K31: un | L31: 84 | M31: =J31*L31
A32: Decoração (opcional) | B32: Suporte de headphone | C32: Suporte de mesa em metal preto | D32: A pesquisar | E32: Estimativa (preço não pesquisado) | F32: — | G32: — | H32: Estimativa | I32: 30/10/2026 | J32: 1 | K32: un | L32: 42 | M32: =J32*L32
... A38: Decoração (opcional) | B38: Caneca e acessórios de mesa | C38: Caneca de cerâmica + porta-lápis | D38: A pesquisar | E38: Estimativa (preço não pesquisado) | F38: — | G38: — | H38: Estimativa | I38: 30/10/2026 | J38: 1 | K38: un | L38: 42 | M38: =J38*L38
A39: Serviços | B39: Mão de obra de pintura | C39: Pintor (paredes + teto), sem preparo pesado | D39: Profissional local | E39: Faixa R$ 15–35/m² simples; R$ 35–60/m² com preparo (Lar Pontual) — https://larpontual.com.br/portal/preco-de-pintor-por-m2 | F39: — | G39: — | H39: Estimativa | I39: 30/10/2026 | J39: =area_pintura_total | K39: m² | L39: 25 | M39: =J39*L39
A40: Serviços | B40: Frete (itens sem frete grátis) | C40: Reserva de frete | D40: — | E40: Estimativa | F40: — | G40: — | H40: Estimativa | I40: 30/10/2026 | J40: 1 | K40: vb | L40: 150 | M40: =J40*L40
L42: Subtotal itens | M42: =SUM(M4:M40)
L43: Reserva para imprevistos | M43: =M42*contingencia
L44: TOTAL | M44: =M42+M43

Sheet Equilibrado
A1: Orçamento — cenário Equilibrado (preços consultados em 30/10/2026)
A3: Categoria | B3: Item | C3: Produto / especificação | D3: Loja / fornecedor | E3: Link / fonte | F3: Dimensões L×P×A (cm) | G3: Material | H3: Status do preço | I3: Data | J3: Qtd | K3: Unid. | L3: Preço unit. | M3: Subtotal
A4: Mobiliário | B4: Mesa regulável elétrica | C4: Pichau Starlift Pro 160×70 — usar a ESTRUTURA (80 kg); o tampo original sobra | D4: Pichau | E4: https://www.pichau.com.br/mesa-pichau-starlift-pro-com-regulagem-de-altura-160x80cm-preto | F4: 160 × 70 × 73–118 | G4: Aço + MDP melamina preto | H4: Pesquisado (página do produto) | I4: 30/10/2026 | J4: 1 | K4: un | L4: 823.99 | M4: =J4*L4
A5: Mobiliário | B5: Tampo sob medida | C5: Tampo MDF 25 mm freijó 170×70, borda reta, furo p/ braço e passa-cabo | D5: Marceneiro local | E5: Estimativa | F5: 170 × 70 × 2,5 | G5: MDF BP freijó | H5: Estimativa | I5: 30/10/2026 | J5: 1 | K5: un | L5: 700 | M5: =J5*L5
A6: Mobiliário | B6: Cadeira ergonômica | C6: DT3 Elin Black 14881-2 (braço 5D, encosto de cabeça 3D, lombar) | D6: Pichau | E6: https://www.pichau.com.br/cadeira-ergonomica-dt3-elin-black-14881-2 | F6: não declarada (est. 65 × 65) | G6: Tecido + nylon | H6: Pesquisado (página do produto) | I6: 30/10/2026 | J6: 1 | K6: un | L6: 1199.99 | M6: =J6*L6
A7: Mobiliário | B7: Cama box + colchão solteiro | C7: Gazin Maximus molas ensacadas, linho grafite/preto | D7: Amazon | E7: https://www.amazon.com.br/dp/B0D1J7X17Z | F7: 88 × 188 × 62 | G7: Molas ensacadas | H7: Pesquisado (listagem da loja) | I7: 30/10/2026 | J7: 1 | K7: un | L7: 899.1 | M7: =J7*L7
A8: Mobiliário | B8: Braço articulado 2 monitores | C8: ELG F160N 17–35" (2–9 kg/braço; borda ou furo) | D8: Amazon | E8: https://www.amazon.com.br/dp/B0765KZDWP | F8: — | G8: Aço/alumínio | H8: Pesquisado (página do produto) | I8: 30/10/2026 | J8: 1 | K8: un | L8: 218.87 | M8: =J8*L8
A9: Marcenaria | B9: Painel ripado Parede D (piso→teto) | C9: Ripado MDF BP freijó + fundo preto, recortes, instalado | D9: Marceneiro local | E9: Faixa R$ 250–600/m² instalado (Revista Oeste); R$ 180–750/m² (Monitor do Mercado) — https://monitordomercado.com.br/economia-2/385193-quanto-custa-instalar-painel-ripado-e-transformar-a-sala-com-um-visual-moderno-e-sofisticado/ | F9: 265 × 3 × 264 | G9: MDF BP freijó | H9: Estimativa | I9: 30/10/2026 | J9: =area_ripado | K9: m² | L9: 400 | M9: =J9*L9
A10: Marcenaria | B10: Prateleira sobre a mesa | C10: Prateleira freijó 170×25 c/ rasgo para LED, h = 1,95 m | D10: Marceneiro local | E10: Estimativa | F10: 170 × 25 × 2,5 | G10: MDF BP freijó | H10: Estimativa | I10: 30/10/2026 | J10: 1 | K10: un | L10: 500 | M10: =J10*L10
A11: Marcenaria | B11: Nichos iluminados 3× (cabeceira) | C11: MDF BP freijó 15 mm, fundo preto, rasgo p/ LED | D11: Marceneiro local | E11: Estimativa | F11: 3 × (24 × 26 × 16) | G11: MDF BP freijó | H11: Estimativa | I11: 30/10/2026 | J11: 1 | K11: vb | L11: 450 | M11: =J11*L11
A12: Iluminação | B12: Fita LED COB 3000 K | C12: Stella All Light Pro 16W/m 24V COB 3000K IRC 95+ 5 m | D12: Amazon | E12: https://www.amazon.com.br/dp/B0F7ZGD3M2 | F12: 5 m | G12: — | H12: Pesquisado (listagem da loja) | I12: 30/10/2026 | J12: =rolos_led | K12: rolo | L12: 200.69 | M12: =J12*L12
A13: Iluminação | B13: Fonte 24 V | C13: Fonte chaveada slim 24V 5A 120W bivolt | D13: Amazon | E13: https://www.amazon.com.br/dp/B0H7CQ2BY2 | F13: — | G13: — | H13: Pesquisado (listagem da loja) | I13: 30/10/2026 | J13: 1 | K13: un | L13: 61.99 | M13: =J13*L13
A14: Iluminação | B14: Perfil de alumínio p/ LED | C14: Perfil LED embutir 24×7 mm slim 2 m preto | D14: Amazon | E14: https://www.amazon.com.br/dp/B0F1ZBZZTP | F14: 200 cm | G14: Alumínio | H14: Pesquisado (listagem da loja) | I14: 30/10/2026 | J14: =barras_perfil | K14: barra | L14: 29.9 | M14: =J14*L14
A15: Iluminação | B15: Controle Wi-Fi da fita | C15: Controlador Wi-Fi c/ dimmer (Alexa/Google) | D15: Amazon | E15: https://www.amazon.com.br/dp/B0FS91PKKL | F15: — | G15: — | H15: Pesquisado (listagem da loja) | I15: 30/10/2026 | J15: 1 | K15: un | L15: 43.02 | M15: =J15*L15
A16: Iluminação | B16: Barra de luz p/ monitor | C16: Quntis Light Bar PRO+ c/ controle remoto | D16: Amazon | E16: https://www.amazon.com.br/dp/B0B6P9J3J5 | F16: — | G16: — | H16: Pesquisado (listagem da loja) | I16: 30/10/2026 | J16: 1 | K16: un | L16: 293.55 | M16: =J16*L16
A17: Iluminação | B17: Arandela da cama | C17: Arandela tubo articulada preta c/ interruptor (conferir se tem plugue) | D17: Amazon | E17: https://www.amazon.com.br/dp/B0DND64VLW | F17: — | G17: Metal | H17: Pesquisado (listagem da loja) | I17: 30/10/2026 | J17: 1 | K17: un | L17: 74.95 | M17: =J17*L17
A18: Iluminação | B18: Lâmpadas 3000 K (ventilador/teto) | C18: LEDVANCE OSRAM CLA60 9W 3000K E27 (kit 10) | D18: Amazon | E18: https://www.amazon.com.br/dp/B0HNY3SPM6 | F18: — | G18: — | H18: Pesquisado (listagem da loja) | I18: 30/10/2026 | J18: 1 | K18: kit | L18: 69.9 | M18: =J18*L18
A19: Pintura | B19: Tinta paredes (grafite) | C19: Suvinil Fosco Completo 3,6 L — preço da base branca; cor grafite em loja (conferir) | D19: Amazon | E19: https://www.amazon.com.br/dp/B077G771GN | F19: 3,6 L | G19: Acrílica fosca | H19: Pesquisado (listagem da loja) | I19: 30/10/2026 | J19: =galoes_parede | K19: galão | L19: 179.9 | M19: =J19*L19
A20: Pintura | B20: Tinta teto (branco) | C20: Suvinil acrílica fosca para teto Branco Neve 3,6 L | D20: Amazon | E20: https://www.amazon.com.br/dp/B077G6GQSP | F20: 3,6 L | G20: Acrílica | H20: Pesquisado (listagem da loja) | I20: 30/10/2026 | J20: =galoes_teto | K20: galão | L20: 171 | M20: =J20*L20
A21: Pintura | B21: Kit pintura | C21: Kit anti-gotas rolos 23/9 cm, bandeja, suporte e trincha | D21: Amazon | E21: https://www.amazon.com.br/dp/B0H6CMVSRL | F21: — | G21: — | H21: Pesquisado (listagem da loja) | I21: 30/10/2026 | J21: 1 | K21: kit | L21: 31.99 | M21: =J21*L21
A22: Pintura | B22: Fita crepe | C22: Kit 2 fitas crepe 48 mm × 50 m | D22: Amazon | E22: https://www.amazon.com.br/dp/B0H8BCLC4J | F22: — | G22: — | H22: Pesquisado (listagem da loja) | I22: 30/10/2026 | J22: 1 | K22: kit | L22: 29.8 | M22: =J22*L22
A23: Pintura | B23: Proteção de piso/móveis | C23: Lona protetora c/ fita 1,5 × 10 m | D23: Amazon | E23: https://www.amazon.com.br/dp/B0GVPX4YVY | F23: — | G23: — | H23: Pesquisado (listagem da loja) | I23: 30/10/2026 | J23: 1 | K23: un | L23: 15.9 | M23: =J23*L23
A24: Pintura | B24: Massa/reparos pontuais | C24: Massa corrida + lixa (reparos) | D24: — | E24: Estimativa | F24: — | G24: — | H24: Estimativa | I24: 30/10/2026 | J24: 1 | K24: vb | L24: 60 | M24: =J24*L24
A25: Complementares | B25: Tapete | C25: Tapete pelo baixo c/ relevo cinza escuro 2,00 × 1,40 | D25: Amazon | E25: https://www.amazon.com.br/dp/B0GXCDQG6W | F25: 140 × 200 | G25: Sintético | H25: Pesquisado (listagem da loja) | I25: 30/10/2026 | J25: 1 | K25: un | L25: 142.4 | M25: =J25*L25
A26: Complementares | B26: Filtro de linha c/ DPS | C26: iCLAMPER Energia 5 tomadas | D26: Amazon | E26: https://www.amazon.com.br/dp/B0D8V17JSG | F26: — | G26: — | H26: Pesquisado (listagem da loja) | I26: 30/10/2026 | J26: 1 | K26: un | L26: 71.98 | M26: =J26*L26
A27: Complementares | B27: Prolongador da tomada (ripado) | C27: Margirius prolongador caixa 4×2 | D27: Amazon | E27: https://www.amazon.com.br/dp/B089M44PPG | F27: — | G27: — | H27: Pesquisado (listagem da loja) | I27: 30/10/2026 | J27: 1 | K27: un | L27: 23.27 | M27: =J27*L27
A28: Complementares | B28: Bandeja de cabos sob a mesa | C28: Bandeja organizadora sem perfuração | D28: Amazon | E28: https://www.amazon.com.br/dp/B0GJRDZM82 | F28: — | G28: Metal | H28: Pesquisado (listagem da loja) | I28: 30/10/2026 | J28: 1 | K28: un | L28: 119.69 | M28: =J28*L28
A29: Complementares | B29: Suporte de notebook | C29: Suporte dobrável alumínio c/ regulagem | D29: Amazon | E29: https://www.amazon.com.br/dp/B0H13G1VTW | F29: — | G29: Alumínio | H29: Pesquisado (listagem da loja) | I29: 30/10/2026 | J29: 1 | K29: un | L29: 65.78 | M29: =J29*L29
A30: Decoração (opcional) | B30: Luminária de mesa articulada | C30: Luminária articulada preta, E27, lâmpada 2700 K | D30: A pesquisar | E30: Estimativa (preço não pesquisado) | F30: — | G30: — | H30: Estimativa | I30: 30/10/2026 | J30: 1 | K30: un | L30: 120 | M30: =J30*L30
A31: Decoração (opcional) | B31: Suporte de headphone | C31: Suporte de mesa em metal preto | D31: A pesquisar | E31: Estimativa (preço não pesquisado) | F31: — | G31: — | H31: Estimativa | I31: 30/10/2026 | J31: 1 | K31: un | L31: 60 | M31: =J31*L31
A32: Decoração (opcional) | B32: Quadros P&B (3 na parede + 2 na prateleira) | C32: Impressões P&B 40×55, 2× 36×26, 20×25, 15×20 c/ moldura preta e passe-partout | D32: A pesquisar | E32: Estimativa (preço não pesquisado) | F32: — | G32: — | H32: Estimativa | I32: 30/10/2026 | J32: 1 | K32: un | L32: 350 | M32: =J32*L32
... A37: Decoração (opcional) | B37: Caneca e acessórios de mesa | C37: Caneca de cerâmica + porta-lápis | D37: A pesquisar | E37: Estimativa (preço não pesquisado) | F37: — | G37: — | H37: Estimativa | I37: 30/10/2026 | J37: 1 | K37: un | L37: 60 | M37: =J37*L37
A38: Serviços | B38: Mão de obra de pintura | C38: Pintor c/ preparo (paredes + teto) | D38: Profissional local | E38: Faixa R$ 15–35/m² simples; R$ 35–60/m² com preparo (Lar Pontual) — https://larpontual.com.br/portal/preco-de-pintor-por-m2 | F38: — | G38: — | H38: Estimativa | I38: 30/10/2026 | J38: =area_pintura_total | K38: m² | L38: 35 | M38: =J38*L38
A39: Serviços | B39: Instalação da iluminação | C39: Montagem das fitas/perfis/fonte (marceneiro ou eletricista) | D39: Profissional local | E39: Estimativa | F39: — | G39: — | H39: Estimativa | I39: 30/10/2026 | J39: 1 | K39: vb | L39: 250 | M39: =J39*L39
A40: Serviços | B40: Frete (itens sem frete grátis) | C40: Reserva de frete | D40: — | E40: Estimativa | F40: — | G40: — | H40: Estimativa | I40: 30/10/2026 | J40: 1 | K40: vb | L40: 200 | M40: =J40*L40
L42: Subtotal itens | M42: =SUM(M4:M40)
L43: Reserva para imprevistos | M43: =M42*contingencia
L44: TOTAL | M44: =M42+M43

Sheet Premium
A1: Orçamento — cenário Premium (preços consultados em 30/10/2026)
A3: Categoria | B3: Item | C3: Produto / especificação | D3: Loja / fornecedor | E3: Link / fonte | F3: Dimensões L×P×A (cm) | G3: Material | H3: Status do preço | I3: Data | J3: Qtd | K3: Unid. | L3: Preço unit. | M3: Subtotal
A4: Mobiliário | B4: Estrutura elétrica motor duplo | C4: Marsail motor duplo 120 kg, 71–118 cm, preta (Amazon Global — importação) | D4: Amazon | E4: https://www.amazon.com.br/dp/B0H45N1KWD | F4: tampos até 230 × 101 | G4: Aço | H4: Pesquisado (página do produto) | I4: 30/10/2026 | J4: 1 | K4: un | L4: 2020.64 | M4: =J4*L4
A5: Mobiliário | B5: Tampo sob medida | C5: Tampo 30 mm lâmina natural freijó 170×70, borda maciça, furo p/ braço | D5: Marceneiro local | E5: Estimativa | F5: 170 × 70 × 3 | G5: MDF + lâmina natural | H5: Estimativa | I5: 30/10/2026 | J5: 1 | K5: un | L5: 1100 | M5: =J5*L5
A6: Mobiliário | B6: Cadeira ergonômica | C6: DT3 Ergonomie Preto 14435-7 | D6: Pichau | E6: https://www.pichau.com.br/cadeira-ergonomica-dt3-ergonomie-preto-14435-7 | F6: não declarada (est. 70 × 70) | G6: Tela | H6: Pesquisado (listagem da loja) | I6: 30/10/2026 | J6: 1 | K6: un | L6: 2599.99 | M6: =J6*L6
A7: Mobiliário | B7: Cama box baú + colchão solteiro | C7: Inducol Real molas ensacadas, box baú (armazenamento) | D7: Amazon | E7: https://www.amazon.com.br/dp/B0D54VM511 | F7: 88 × 188 × 68 | G7: Molas ensacadas | H7: Pesquisado (listagem da loja) | I7: 30/10/2026 | J7: 1 | K7: un | L7: 1169.1 | M7: =J7*L7
A8: Mobiliário | B8: Braço articulado 2 monitores | C8: ELG F196dp 17–35" grafite, c/ cabo DisplayPort | D8: Amazon | E8: https://www.amazon.com.br/dp/B0HKLNT1LN | F8: — | G8: Aço/alumínio | H8: Pesquisado (listagem da loja) | I8: 30/10/2026 | J8: 1 | K8: un | L8: 284.99 | M8: =J8*L8
A9: Marcenaria | B9: Painel ripado Parede D (piso→teto) | C9: Ripado em lâmina natural freijó + fundo preto, instalado | D9: Marceneiro local | E9: Faixa R$ 250–600/m² instalado (Revista Oeste); R$ 180–750/m² (Monitor do Mercado) — https://monitordomercado.com.br/economia-2/385193-quanto-custa-instalar-painel-ripado-e-transformar-a-sala-com-um-visual-moderno-e-sofisticado/ | F9: 265 × 3 × 264 | G9: Lâmina natural | H9: Estimativa | I9: 30/10/2026 | J9: =area_ripado | K9: m² | L9: 600 | M9: =J9*L9
A10: Marcenaria | B10: Prateleira sobre a mesa | C10: Prateleira lâmina natural 170×25 c/ LED embutido, h = 1,95 m | D10: Marceneiro local | E10: Estimativa | F10: 170 × 25 × 3 | G10: Lâmina natural | H10: Estimativa | I10: 30/10/2026 | J10: 1 | K10: un | L10: 800 | M10: =J10*L10
A11: Marcenaria | B11: Nichos iluminados 3× (cabeceira) | C11: Lâmina natural freijó, fundo preto, LED embutido | D11: Marceneiro local | E11: Estimativa | F11: 3 × (24 × 26 × 16) | G11: Lâmina natural | H11: Estimativa | I11: 30/10/2026 | J11: 1 | K11: vb | L11: 700 | M11: =J11*L11
A12: Iluminação | B12: Fita LED COB 3000 K | C12: Stella All Light Pro 16W/m 24V COB 3000K IRC 95+ 5 m | D12: Amazon | E12: https://www.amazon.com.br/dp/B0F7ZGD3M2 | F12: 5 m | G12: — | H12: Pesquisado (listagem da loja) | I12: 30/10/2026 | J12: =rolos_led_prem | K12: rolo | L12: 200.69 | M12: =J12*L12
A13: Iluminação | B13: Fonte 24 V | C13: Fonte chaveada slim 24V 5A 120W bivolt | D13: Amazon | E13: https://www.amazon.com.br/dp/B0H7CQ2BY2 | F13: — | G13: — | H13: Pesquisado (listagem da loja) | I13: 30/10/2026 | J13: 2 | K13: un | L13: 61.99 | M13: =J13*L13
A14: Iluminação | B14: Perfil de alumínio p/ LED | C14: Perfil LED embutir 24×7 mm slim 2 m preto | D14: Amazon | E14: https://www.amazon.com.br/dp/B0F1ZBZZTP | F14: 200 cm | G14: Alumínio | H14: Pesquisado (listagem da loja) | I14: 30/10/2026 | J14: =barras_perfil_prem | K14: barra | L14: 29.9 | M14: =J14*L14
A15: Iluminação | B15: Controle Wi-Fi da fita | C15: Controlador Wi-Fi c/ dimmer (Alexa/Google) | D15: Amazon | E15: https://www.amazon.com.br/dp/B0FS91PKKL | F15: — | G15: — | H15: Pesquisado (listagem da loja) | I15: 30/10/2026 | J15: 2 | K15: un | L15: 43.02 | M15: =J15*L15
A16: Iluminação | B16: Barra de luz p/ monitor | C16: BenQ ScreenBar Pro (sensor de presença) | D16: Amazon | E16: https://www.amazon.com.br/dp/B0CZ9P1QW9 | F16: — | G16: — | H16: Pesquisado (listagem da loja) | I16: 30/10/2026 | J16: 1 | K16: un | L16: 1389.2 | M16: =J16*L16
A17: Iluminação | B17: Arandela da cama | C17: GOODATE arandela plug-in c/ interruptor regulável, braço oscilante | D17: Amazon | E17: https://www.amazon.com.br/dp/B094QSBVNB | F17: — | G17: Metal | H17: Pesquisado (listagem da loja) | I17: 30/10/2026 | J17: 1 | K17: un | L17: 344.79 | M17: =J17*L17
A18: Iluminação | B18: Lâmpadas 3000 K (ventilador/teto) | C18: LEDVANCE OSRAM CLA60 9W 3000K E27 (kit 10) | D18: Amazon | E18: https://www.amazon.com.br/dp/B0HNY3SPM6 | F18: — | G18: — | H18: Pesquisado (listagem da loja) | I18: 30/10/2026 | J18: 1 | K18: kit | L18: 69.9 | M18: =J18*L18
A19: Pintura | B19: Tinta paredes (grafite) | C19: Suvinil Toque de Seda acetinado 3,6 L — preço da base branca; cor em loja (conferir) | D19: Amazon | E19: https://www.amazon.com.br/dp/B077G8JCN6 | F19: 3,6 L | G19: Acrílica acetinada | H19: Pesquisado (listagem da loja) | I19: 30/10/2026 | J19: =galoes_parede | K19: galão | L19: 206.1 | M19: =J19*L19
A20: Pintura | B20: Tinta teto (branco) | C20: Suvinil acrílica fosca para teto Branco Neve 3,6 L | D20: Amazon | E20: https://www.amazon.com.br/dp/B077G6GQSP | F20: 3,6 L | G20: Acrílica | H20: Pesquisado (listagem da loja) | I20: 30/10/2026 | J20: =galoes_teto | K20: galão | L20: 171 | M20: =J20*L20
A21: Pintura | B21: Selador acrílico | C21: Selador acrílico 3,6 L | D21: Amazon | E21: https://www.amazon.com.br/dp/B0HCR49N2B | F21: 3,6 L | G21: — | H21: Pesquisado (listagem da loja) | I21: 30/10/2026 | J21: 1 | K21: galão | L21: 40.4 | M21: =J21*L21
A22: Pintura | B22: Kit pintura | C22: Kit anti-gotas rolos 23/9 cm, bandeja, suporte e trincha | D22: Amazon | E22: https://www.amazon.com.br/dp/B0H6CMVSRL | F22: — | G22: — | H22: Pesquisado (listagem da loja) | I22: 30/10/2026 | J22: 1 | K22: kit | L22: 31.99 | M22: =J22*L22
A23: Pintura | B23: Fita crepe | C23: Kit 2 fitas crepe 48 mm × 50 m | D23: Amazon | E23: https://www.amazon.com.br/dp/B0H8BCLC4J | F23: — | G23: — | H23: Pesquisado (listagem da loja) | I23: 30/10/2026 | J23: 1 | K23: kit | L23: 29.8 | M23: =J23*L23
A24: Pintura | B24: Proteção de piso/móveis | C24: Lona protetora c/ fita 1,5 × 10 m | D24: Amazon | E24: https://www.amazon.com.br/dp/B0GVPX4YVY | F24: — | G24: — | H24: Pesquisado (listagem da loja) | I24: 30/10/2026 | J24: 1 | K24: un | L24: 15.9 | M24: =J24*L24
A25: Pintura | B25: Massa/reparos | C25: Massa corrida + lixa | D25: — | E25: Estimativa | F25: — | G25: — | H25: Estimativa | I25: 30/10/2026 | J25: 1 | K25: vb | L25: 90 | M25: =J25*L25
A26: Complementares | B26: Tapete | C26: Tapete pelo baixo c/ relevo cinza escuro 2,00 × 1,40 | D26: Amazon | E26: https://www.amazon.com.br/dp/B0GXCDQG6W | F26: 140 × 200 | G26: Sintético | H26: Pesquisado (listagem da loja) | I26: 30/10/2026 | J26: 1 | K26: un | L26: 142.4 | M26: =J26*L26
A27: Complementares | B27: Filtro de linha c/ DPS | C27: iCLAMPER Energia 5 tomadas | D27: Amazon | E27: https://www.amazon.com.br/dp/B0D8V17JSG | F27: — | G27: — | H27: Pesquisado (listagem da loja) | I27: 30/10/2026 | J27: 1 | K27: un | L27: 71.98 | M27: =J27*L27
A28: Complementares | B28: Prolongador da tomada (ripado) | C28: Margirius prolongador caixa 4×2 | D28: Amazon | E28: https://www.amazon.com.br/dp/B089M44PPG | F28: — | G28: — | H28: Pesquisado (listagem da loja) | I28: 30/10/2026 | J28: 1 | K28: un | L28: 23.27 | M28: =J28*L28
A29: Complementares | B29: Suporte de notebook | C29: Suporte aço carbono base giratória 360° | D29: Amazon | E29: https://www.amazon.com.br/dp/B0HFNYSZHZ | F29: — | G29: Aço | H29: Pesquisado (listagem da loja) | I29: 30/10/2026 | J29: 1 | K29: un | L29: 109.15 | M29: =J29*L29
A30: Decoração (opcional) | B30: Luminária de mesa articulada | C30: Luminária articulada preta, E27, lâmpada 2700 K | D30: A pesquisar | E30: Estimativa (preço não pesquisado) | F30: — | G30: — | H30: Estimativa | I30: 30/10/2026 | J30: 1 | K30: un | L30: 192 | M30: =J30*L30
A31: Decoração (opcional) | B31: Suporte de headphone | C31: Suporte de mesa em metal preto | D31: A pesquisar | E31: Estimativa (preço não pesquisado) | F31: — | G31: — | H31: Estimativa | I31: 30/10/2026 | J31: 1 | K31: un | L31: 96 | M31: =J31*L31
A32: Decoração (opcional) | B32: Quadros P&B (3 na parede + 2 na prateleira) | C32: Impressões P&B 40×55, 2× 36×26, 20×25, 15×20 c/ moldura preta e passe-partout | D32: A pesquisar | E32: Estimativa (preço não pesquisado) | F32: — | G32: — | H32: Estimativa | I32: 30/10/2026 | J32: 1 | K32: un | L32: 560 | M32: =J32*L32
... A37: Decoração (opcional) | B37: Caneca e acessórios de mesa | C37: Caneca de cerâmica + porta-lápis | D37: A pesquisar | E37: Estimativa (preço não pesquisado) | F37: — | G37: — | H37: Estimativa | I37: 30/10/2026 | J37: 1 | K37: un | L37: 96 | M37: =J37*L37
A38: Serviços | B38: Mão de obra de pintura | C38: Pintor c/ preparo completo (paredes + teto) | D38: Profissional local | E38: Faixa R$ 15–35/m² simples; R$ 35–60/m² com preparo (Lar Pontual) — https://larpontual.com.br/portal/preco-de-pintor-por-m2 | F38: — | G38: — | H38: Estimativa | I38: 30/10/2026 | J38: =area_pintura_total | K38: m² | L38: 55 | M38: =J38*L38
A39: Serviços | B39: Instalação da iluminação | C39: Montagem das fitas/perfis/fontes (marceneiro ou eletricista) | D39: Profissional local | E39: Estimativa | F39: — | G39: — | H39: Estimativa | I39: 30/10/2026 | J39: 1 | K39: vb | L39: 400 | M39: =J39*L39
A40: Serviços | B40: Frete e taxas de importação | C40: Reserva (Amazon Global pode ter impostos) | D40: — | E40: Estimativa | F40: — | G40: — | H40: Estimativa | I40: 30/10/2026 | J40: 1 | K40: vb | L40: 450 | M40: =J40*L40
L42: Subtotal itens | M42: =SUM(M4:M40)
L43: Reserva para imprevistos | M43: =M42*contingencia
L44: TOTAL | M44: =M42+M43

Sheet Quantitativos
A1: Quantitativos técnicos — altere os valores em azul; o resto recalcula
A3: Nome | B3: Descrição | C3: Valor | D3: Unid. | E3: Status
A4: pe_direito | B4: Pé-direito | C4: 2.64 | D4: m | E4: Confirmada
A5: parede_e_comp | B5: Parede E — comprimento | C5: 2.85 | D5: m | E5: Confirmada
A6: janela_l | B6: Janela — largura | C6: 1.45 | D6: m | E6: Calculada
A7: janela_h | B7: Janela — altura | C7: 1.2 | D7: m | E7: Confirmada*
A8: parede_c_comp | B8: Parede C — comprimento | C8: 2 | D8: m | E8: Confirmada
A9: bwc_trechos | B9: Parede do banheiro voltada à faixa (sem o vão da porta) | C9: 1.12 | D9: m | E9: Calculada
A10: porta_bwc_l | B10: Porta do banheiro c/ batente | C10: 0.73 | D10: m | E10: Confirmada
A11: porta_h | B11: Altura das portas (padrão) | C11: 2.1 | D11: m | E11: Estimada
A12: faixa | B12: Faixa de entrada (parede leste) | C12: 0.86 | D12: m | E12: Confirmada
A13: porta_ent_l | B13: Porta de entrada c/ batente | C13: 0.8 | D13: m | E13: Confirmada
A14: parede_d_comp | B14: Parede D — comprimento | C14: 2.65 | D14: m | E14: Confirmada
A15: teto_faixa_l | B15: Faixa de entrada — comprimento | C15: 1.95 | D15: m | E15: Calculada
A16: area_e | B16: Área Parede E (− janela) | C16: =parede_e_comp*pe_direito-janela_l*janela_h | D16: m² | E16: Calculada
A17: area_c | B17: Área Parede C | C17: =parede_c_comp*pe_direito | D17: m² | E17: Calculada
A18: area_bwc | B18: Área parede do banheiro (+ acima da porta) | C18: =bwc_trechos*pe_direito+porta_bwc_l*(pe_direito-porta_h) | D18: m² | E18: Calculada
A19: area_leste | B19: Área parede leste (− porta) | C19: =faixa*pe_direito-porta_ent_l*porta_h | D19: m² | E19: Calculada
A20: area_paredes | B20: TOTAL paredes grafite | C20: =area_e+area_c+area_bwc+area_leste | D20: m² | E20: Calculada
A21: area_teto | B21: Área do teto | C21: =parede_d_comp*parede_e_comp+teto_faixa_l*faixa | D21: m² | E21: Calculada
A22: area_pintura_total | B22: Área total de pintura (paredes + teto) | C22: =area_paredes+area_teto | D22: m² | E22: Calculada
A23: area_ripado | B23: Área do ripado (Parede D inteira) | C23: =parede_d_comp*pe_direito | D23: m² | E23: Calculada
A24: demaos_parede | B24: Demãos nas paredes (cor escura sobre clara) | C24: 3 | D24: un | E24: Premissa
A25: demaos_teto | B25: Demãos no teto | C25: 2 | D25: un | E25: Premissa
A26: perda_tinta | B26: Perda de tinta | C26: 0.1 | D26: % | E26: Premissa
A27: rend_galao | B27: Rendimento por galão 3,6 L por demão (conservador; conferir embalagem) | C27: 40 | D27: m² | E27: Estimada
A28: galoes_parede | B28: Galões para paredes | C28: =ROUNDUP(area_paredes*demaos_parede*(1+perda_tinta)/rend_galao,0) | D28: galão | E28: Calculada
A29: galoes_teto | B29: Galões para teto | C29: =ROUNDUP(area_teto*demaos_teto*(1+perda_tinta)/rend_galao,0) | D29: galão | E29: Calculada
A30: led_prateleira | B30: LED sob a prateleira | C30: 1.7 | D30: m | E30: Projeto
A31: led_vertical | B31: LED vertical no ripado (por perfil) | C31: 2.4 | D31: m | E31: Projeto
A32: led_nichos | B32: LED dos 3 nichos (3 × 0,24) | C32: 0.72 | D32: m | E32: Projeto
A33: n_verticais | B33: Nº de perfis verticais (Econômico/Equilibrado) | C33: 1 | D33: un | E33: Projeto
A34: perda_led | B34: Sobra de corte da fita | C34: 0.1 | D34: % | E34: Premissa
A35: metros_led | B35: Metros de fita LED | C35: =(led_prateleira+led_vertical*n_verticais+led_nichos)*(1+perda_led) | D35: m | E35: Calculada
A36: rolos_led | B36: Rolos de 5 m | C36: =ROUNDUP(metros_led/5,0) | D36: rolo | E36: Calculada
A37: barras_perfil | B37: Barras de perfil de 2 m | C37: =ROUNDUP(led_prateleira/2,0)+n_verticais*ROUNDUP(led_vertical/2,0) | D37: barra | E37: Calculada
A38: n_verticais_prem | B38: Nº de perfis verticais — Premium | C38: 2 | D38: un | E38: Projeto
A39: metros_led_prem | B39: Metros de fita LED — Premium | C39: =(led_prateleira+led_vertical*n_verticais_prem+led_nichos)*(1+perda_led) | D39: m | E39: Calculada
A40: rolos_led_prem | B40: Rolos de 5 m — Premium | C40: =ROUNDUP(metros_led_prem/5,0) | D40: rolo | E40: Calculada
A41: barras_perfil_prem | B41: Barras de perfil de 2 m — Premium | C41: =ROUNDUP(led_prateleira/2,0)+n_verticais_prem*ROUNDUP(led_vertical/2,0) | D41: barra | E41: Calculada
...
